[0m15:09:28.876880 [debug] [MainThread]: Sending event: {'category': 'dbt', 'action': 'invocation', 'label': 'start', 'context': [<snowplow_tracker.self_describing_json.SelfDescribingJson object at 0x1085495b0>, <snowplow_tracker.self_describing_json.SelfDescribingJson object at 0x108a3e6f0>, <snowplow_tracker.self_describing_json.SelfDescribingJson object at 0x108a3e2d0>]}


============================== 15:09:28.882058 | d7fc3b5a-b37a-4562-8a96-a747eb2d161c ==============================
[0m15:09:28.882058 [info ] [MainThread]: Running with dbt=1.9.1
[0m15:09:28.882948 [debug] [MainThread]: running dbt with arguments {'printer_width': '80', 'indirect_selection': 'eager', 'log_cache_events': 'False', 'write_json': 'True', 'partial_parse': 'True', 'cache_selected_only': 'False', 'warn_error': 'None', 'debug': 'False', 'version_check': 'True', 'log_path': '/Users/mirnawong/Documents/dbt-jsonschema/tests/1.5/invalid/logs', 'profiles_dir': '/Users/mirnawong/.dbt', 'fail_fast': 'False', 'use_colors': 'True', 'use_experimental_parser': 'False', 'empty': 'None', 'quiet': 'False', 'no_print': 'None', 'log_format': 'default', 'invocation_command': 'dbt ', 'warn_error_options': 'WarnErrorOptions(include=[], exclude=[])', 'static_parser': 'True', 'target_path': 'None', 'introspect': 'True', 'send_anonymous_usage_stats': 'True'}
[0m15:09:28.997505 [error] [MainThread]: Encountered an error:
'version'
[0m15:09:29.000416 [error] [MainThread]: Traceback (most recent call last):
  File "/Users/mirnawong/Library/Python/3.12/lib/python/site-packages/dbt/cli/requires.py", line 153, in wrapper
    result, success = func(*args, **kwargs)
                      ^^^^^^^^^^^^^^^^^^^^^
  File "/Users/mirnawong/Library/Python/3.12/lib/python/site-packages/dbt/cli/requires.py", line 103, in wrapper
    return func(*args, **kwargs)
           ^^^^^^^^^^^^^^^^^^^^^
  File "/Users/mirnawong/Library/Python/3.12/lib/python/site-packages/dbt/cli/requires.py", line 218, in wrapper
    return func(*args, **kwargs)
           ^^^^^^^^^^^^^^^^^^^^^
  File "/Users/mirnawong/Library/Python/3.12/lib/python/site-packages/dbt/cli/requires.py", line 251, in wrapper
    project = load_project(
              ^^^^^^^^^^^^^
  File "/Users/mirnawong/Library/Python/3.12/lib/python/site-packages/dbt/config/runtime.py", line 59, in load_project
    project = Project.from_project_root(
              ^^^^^^^^^^^^^^^^^^^^^^^^^^
  File "/Users/mirnawong/Library/Python/3.12/lib/python/site-packages/dbt/config/project.py", line 749, in from_project_root
    return partial.render(renderer)
           ^^^^^^^^^^^^^^^^^^^^^^^^
  File "/Users/mirnawong/Library/Python/3.12/lib/python/site-packages/dbt/config/project.py", line 318, in render
    return self.create_project(rendered)
           ^^^^^^^^^^^^^^^^^^^^^^^^^^^^^
  File "/Users/mirnawong/Library/Python/3.12/lib/python/site-packages/dbt/config/project.py", line 465, in create_project
    packages: PackageConfig = package_config_from_data(
                              ^^^^^^^^^^^^^^^^^^^^^^^^^
  File "/Users/mirnawong/Library/Python/3.12/lib/python/site-packages/dbt/config/project.py", line 139, in package_config_from_data
    PackageConfig.validate(packages_data)
  File "/Users/mirnawong/Library/Python/3.12/lib/python/site-packages/dbt/contracts/project.py", line 129, in validate
    if not package["version"]:
           ~~~~~~~^^^^^^^^^^^
KeyError: 'version'

[0m15:09:29.002468 [debug] [MainThread]: Resource report: {"command_name": "deps", "command_success": false, "command_wall_clock_time": 0.2098565, "process_in_blocks": "0", "process_kernel_time": 0.147571, "process_mem_max_rss": "92700672", "process_out_blocks": "0", "process_user_time": 0.924053}
[0m15:09:29.002751 [debug] [MainThread]: Command `cli deps` failed at 15:09:29.002695 after 0.21 seconds
[0m15:09:29.002935 [debug] [MainThread]: Sending event: {'category': 'dbt', 'action': 'invocation', 'label': 'end', 'context': [<snowplow_tracker.self_describing_json.SelfDescribingJson object at 0x108848ef0>, <snowplow_tracker.self_describing_json.SelfDescribingJson object at 0x1088d2d20>, <snowplow_tracker.self_describing_json.SelfDescribingJson object at 0x108a3dc70>]}
[0m15:09:29.003133 [debug] [MainThread]: Flushing usage events
[0m15:09:29.772546 [debug] [MainThread]: An error was encountered while trying to flush usage events
